Workbook

Sheet Forutsetninger
A1: KNOTTEN – BOLIGPROSJEKT
A2: Forutsetninger for månedlig energiregnskap
A3: Blå tall = inndata som kan endres. Sorte tall = beregnet.
A5: Total forbruk | B5: Verdi | C5: Presisering | D5: Nøyaktighet / vurdering
A6: Antall boliger | B6: 30 | D6: Sikker – fastsatt i prosjektet
A7: El-forbruk per bolig (utenom oppvarming) | B7: 7000 | D7: usikkert
A8: Netto varmebehov per bolig (rom + tappevann) | B8: 15000 | D8: usikkert
A9: El-forbruk kontorbygg | B9: 37500 | D9: ±30 % – ikke prosjektert. Avhenger av ventilasjon, kjøling og driftstid
A10: El-forbruk lager | B10: 22000 | D10: ±30 % – ikke prosjektert. Avhenger av om lageret er oppvarmet/kjølt
A11: Sum el-forbruk kontor + lager | B11: =B9+B10 -> 59500 | D11: Beregnet – arver usikkerheten i radene over
A12: Sum el-behov boliger | B12: =B6*B7 -> 210000 | D12: Beregnet – arver usikkerheten i radene over
A13: Sum netto varmebehov boliger | B13: =B6*B8 -> 450000 | D13: Beregnet – arver usikkerheten i radene over
A14: TOTALT ENERGIBEHOV PROSJEKTET (el + varme) | B14: =B11+B12+B13 -> 719500 | D14: Beregnet – realistisk spenn ca. ±25 % rundt denne verdien
A16: PRODUKSJON – SOLCELLER (PV) | B16: Verdi | C16: Presisering | D16: Nøyaktighet / vurdering
A17: Takareal tilgjengelig per bolig | B17: 30 | D17: ±15 % – avhenger av takform, orientering og tekniske gjennomføringer
A18: Takareal kontorbygg + lager | B18: 300 | D18: ±20 % – grovt anslag fra volumskisse
A19: Sum tilgjengelig takareal | B19: =B6*B17+B18 -> 1200 | D19: Beregnet
A20: Utnyttelsesgrad av takareal | B20: 0.75 | C20: Luker, kanter, teknikk | D20: ±10 %-poeng – normalt 70–85 % avhengig av luker, kanter og teknisk utstyr på tak
A21: Netto modulareal | B21: =B19*B20 -> 900 | D21: Beregnet
A22: Modulvirkningsgrad | B22: 0.31 | C22: Ved STC | D22: For høyt satt – standardmoduler ligger i dag på 20–23 % ved STC. Bør reduseres, dette gir ca. 30 % for høy solproduksjon
A23: Installert effekt | B23: =B21*B22 -> 279 | C23: 1 kW/m² ved STC | D23: Beregnet
A24: Produksjonsfaktor (energiutbytte) | B24: 970 | D24: ±10 % – typisk 850–1000 kWh/kWp i Sør-Norge ved god orientering, lavere lengre nord
A25: Systemvirkningsgrad (samlede tap) | B25: 0.9 | C25: Inverter, snø, skygge, temperatur | D25: ±5 %-poeng – erfaringstall for tap i inverter, snø, skygge og temperatur
A26: Årsproduksjon solstrøm | B26: =B23*B24*B25 -> 243567 | D26: Beregnet
A27: Spesifikk produksjon (kontroll) | B27: =B26/B23 -> 873 | D27: Kontrolltall – bør ligge på 750–950 kWh/kWp/år
A29: PRODUKSJON – VINDTURBINER | B29: Verdi | C29: Presisering | D29: Nøyaktighet / vurdering
A30: Antall turbiner | B30: 3 | D30: Valgt inndata
A31: Nominell effekt per turbin | B31: 8 | D31: Valgt inndata – må tilpasses faktisk turbinmodell
A32: Installert effekt vind | B32: =B30*B31 -> 24 | D32: Beregnet
A33: Kapasitetsfaktor | B33: 0.25 | C33: Av installert effekt over året | D33: Svært usikker, Krever vindmåling på tomta
A34: Tilgjengelighet og tekniske tap | B34: 0.8 | C34: Drift, vedlikehold, nettap | D34: ±10 %-poeng – erfaringstall, avhenger av drift og vedlikehold
A35: Årsproduksjon vindkraft | B35: =B32*8760*B33*B34 -> 42048 | D35: Modellens mest usikre produksjonstall
A36: Fullasttimer (kontroll) | B36: =B35/B32 -> 1752 | D36: Kontrolltall – småturbiner i innlandet ligger typisk på 900–1800 h/år
A38: SESONGLAGRING I BERG (REGENERERING) | B38: Verdi | C38: Presisering | D38: Nøyaktighet / vurdering
A39: Strøm til regenerering av brønner | B39: 20000 | C39: Fra sommeroverskudd | D39: Ditt valg – sett ikke høyere enn overskuddet du faktisk har. Sammenlign med «Solgt til nett» på Energiregnskap
A40: Varmefaktor ved lading av berg | B40: 3 | C40: Varme til grunnen per kWh strøm | D40: ±1,0 – varmepumpe i kjøledrift gir 3–5. Direkte elkolbe gir 1,0. Solfanger på tak ville gitt gratis lading
A41: Varme tilført grunnen | B41: =B39*B40 -> 60000 | D41: Beregnet
A42: Lagringsvirkningsgrad i berg | B42: 0.6 | C42: Som kan hentes ut igjen | D42: ±15 %-poeng – svært usikkert. Varme siver bort i berget. Avhenger av brønngeometri og grunnvannsstrøm, krever geoteknisk vurdering
A43: Gjenvinnbart tillegg til uttak | B43: =B41*B42 -> 36000 | D43: Beregnet – legges til uttaket fra brønnene i blokken under
A45: VARMELØSNING – BERGVARME | B45: Verdi | C45: Presisering | D45: Nøyaktighet / vurdering
...

Sheet Energiregnskap
A1: KNOTTEN – MÅNEDLIG ENERGIREGNSKAP
A2: 30 boliger + kontorbygg og lager · solceller, vindturbiner, bergvarme og batterilagring · alle energitall i kWh
A3: Alle beregninger henter inndata fra fanen Forutsetninger. Endre inndata der – tabellen oppdateres automatisk. Profilkolonnene C–H kan skjules med +/- over kolonneheadingen.
A5: PERIODE | C5: FORDELINGSPROFIL | I5: ENERGIBEHOV OG VARMEDEKNING | Q5: EGENPRODUKSJON SOL OG VIND | V5: LAGRING (BATTERI) | Y5: NETTUTVEKSLING | AB5: ØKONOMI OG KLIMA
A6: Måned | B6: Dager | C6: El % | D6: Varme % | E6: Sol % | F6: Vind % | G6: Bergvarme % | H6: Prisfaktor | I6: El-behov boliger | J6: El-behov kontor + lager | K6: Netto varmebehov | L6: Varme fra bergvarme | M6: El-forbruk bergvarme | N6: El til spisslast varme | O6: El til regenerering av berg | P6: Sum el-behov | Q6: Produsert solstrøm | R6: Produsert vindkraft | S6: Sum egenproduksjon | T6: Direkte egenbruk | U6: Overskudd til lagring/salg | V6: Ladet inn | W6: Utladet til forbruk | X6: Lagringstap | Y6: Kjøpt fra nett | Z6: Solgt til nett | AA6: Selvforsyningsgrad | AB6: Strømkostnad (kr) | AC6: Salgsinntekt (kr) | AD6: Netto energikostnad (kr) | AE6: Referanse uten tiltak (kr) | AF6: Besparelse (kr) | AG6: Spart CO₂ (kg)
A7: Januar | B7: 31 | C7: 0.095 | D7: 0.15 | E7: 0.01 | F7: 0.11 | G7: 0.14 | H7: 1.3 | I7: =Forutsetninger!$B$12*C7 -> 19950 | J7: =Forutsetninger!$B$11*C7 -> 5652.5 | K7: =Forutsetninger!$B$13*D7 -> 67500 | L7: =MIN(K7,Forutsetninger!$B$48*G7) -> 67500 | M7: =L7/Forutsetninger!$B$47 -> 18750 | N7: =K7-L7 -> 0 | O7: =Forutsetninger!$B$39*E7 -> 200 | P7: =I7+J7+M7+N7+O7 -> 44552.5 | Q7: =Forutsetninger!$B$26*E7 -> 2435.67 | R7: =Forutsetninger!$B$35*F7 -> 4625.28 | S7: =Q7+R7 -> 7060.95 | T7: =MIN(Q7*Forutsetninger!$B$65+R7*Forutsetninger!$B$66,P7) -> 3749.436 | U7: =S7-T7 -> 3311.514 | V7: =MIN(U7,(P7-T7)/Forutsetninger!$B$54,Forutsetninger!$B$53*Forutsetninger!$B$55*B7) -> 3311.514 | W7: =V7*Forutsetninger!$B$54 -> 2980.3626 | X7: =V7-W7 -> 331.1514 | Y7: =P7-T7-W7 -> 37822.701 | Z7: =U7-V7 -> 0 | AA7: =(T7+W7)/P7 -> 0.15105322 | AB7: =Y7*(Forutsetninger!$B$58*H7+Forutsetninger!$B$59) -> 102121.29 | AC7: =Z7*Forutsetninger!$B$61*H7 -> 0 | AD7: =AB7-AC7 -> 102121.29 | AE7: =(I7+J7+K7)*(Forutsetninger!$B$58*H7+Forutsetninger!$B$59) -> 251376.75 | AF7: =AE7-AD7 -> 149255.46 | AG7: =(I7+J7+K7-Y7)*Forutsetninger!$B$62 -> 11055.96
A8: Februar | B8: 28 | C8: 0.09 | D8: 0.13 | E8: 0.03 | F8: 0.1 | G8: 0.12 | H8: 1.25 | I8: =Forutsetninger!$B$12*C8 -> 18900 | J8: =Forutsetninger!$B$11*C8 -> 5355 | K8: =Forutsetninger!$B$13*D8 -> 58500 | L8: =MIN(K8,Forutsetninger!$B$48*G8) -> 58500 | M8: =L8/Forutsetninger!$B$47 -> 16250 | N8: =K8-L8 -> 0 | O8: =Forutsetninger!$B$39*E8 -> 600 | P8: =I8+J8+M8+N8+O8 -> 41105 | Q8: =Forutsetninger!$B$26*E8 -> 7307.01 | R8: =Forutsetninger!$B$35*F8 -> 4204.8 | S8: =Q8+R8 -> 11511.81 | T8: =MIN(Q8*Forutsetninger!$B$65+R8*Forutsetninger!$B$66,P8) -> 5445.684 | U8: =S8-T8 -> 6066.126 | V8: =MIN(U8,(P8-T8)/Forutsetninger!$B$54,Forutsetninger!$B$53*Forutsetninger!$B$55*B8) -> 6066.126 | W8: =V8*Forutsetninger!$B$54 -> 5459.5134 | X8: =V8-W8 -> 606.6126 | Y8: =P8-T8-W8 -> 30199.803 | Z8: =U8-V8 -> 0 | AA8: =(T8+W8)/P8 -> 0.265301 | AB8: =Y8*(Forutsetninger!$B$58*H8+Forutsetninger!$B$59) -> 78519.487 | AC8: =Z8*Forutsetninger!$B$61*H8 -> 0 | AD8: =AB8-AC8 -> 78519.487 | AE8: =(I8+J8+K8)*(Forutsetninger!$B$58*H8+Forutsetninger!$B$59) -> 215163 | AF8: =AE8-AD8 -> 136643.51 | AG8: =(I8+J8+K8-Y8)*Forutsetninger!$B$62 -> 10511.039
A9: Mars | B9: 31 | C9: 0.09 | D9: 0.12 | E9: 0.08 | F9: 0.09 | G9: 0.1 | H9: 1.15 | I9: =Forutsetninger!$B$12*C9 -> 18900 | J9: =Forutsetninger!$B$11*C9 -> 5355 | K9: =Forutsetninger!$B$13*D9 -> 54000 | L9: =MIN(K9,Forutsetninger!$B$48*G9) -> 49984.615 | M9: =L9/Forutsetninger!$B$47 -> 13884.615 | N9: =K9-L9 -> 4015.3846 | O9: =Forutsetninger!$B$39*E9 -> 1600 | P9: =I9+J9+M9+N9+O9 -> 43755 | Q9: =Forutsetninger!$B$26*E9 -> 19485.36 | R9: =Forutsetninger!$B$35*F9 -> 3784.32 | S9: =Q9+R9 -> 23269.68 | T9: =MIN(Q9*Forutsetninger!$B$65+R9*Forutsetninger!$B$66,P9) -> 10064.736 | U9: =S9-T9 -> 13204.944 | V9: =MIN(U9,(P9-T9)/Forutsetninger!$B$54,Forutsetninger!$B$53*Forutsetninger!$B$55*B9) -> 13020 | W9: =V9*Forutsetninger!$B$54 -> 11718 | X9: =V9-W9 -> 1302 | Y9: =P9-T9-W9 -> 21972.264 | Z9: =U9-V9 -> 184.944 | AA9: =(T9+W9)/P9 -> 0.49783421 | AB9: =Y9*(Forutsetninger!$B$58*H9+Forutsetninger!$B$59) -> 52733.434 | AC9: =Z9*Forutsetninger!$B$61*H9 -> 159.5142 | AD9: =AB9-AC9 -> 52573.919 | AE9: =(I9+J9+K9)*(Forutsetninger!$B$58*H9+Forutsetninger!$B$59) -> 187812 | AF9: =AE9-AD9 -> 135238.08 | AG9: =(I9+J9+K9-Y9)*Forutsetninger!$B$62 -> 11256.547
A10: April | B10: 30 | C10: 0.085 | D10: 0.09 | E10: 0.12 | F10: 0.08 | G10: 0.08 | H10: 1 | I10: =Forutsetninger!$B$12*C10 -> 17850 | J10: =Forutsetninger!$B$11*C10 -> 5057.5 | K10: =Forutsetninger!$B$13*D10 -> 40500 | L10: =MIN(K10,Forutsetninger!$B$48*G10) -> 39987.692 | M10: =L10/Forutsetninger!$B$47 -> 11107.692 | N10: =K10-L10 -> 512.30769 | O10: =Forutsetninger!$B$39*E10 -> 2400 | P10: =I10+J10+M10+N10+O10 -> 36927.5 | Q10: =Forutsetninger!$B$26*E10 -> 29228.04 | R10: =Forutsetninger!$B$35*F10 -> 3363.84 | S10: =Q10+R10 -> 32591.88 | T10: =MIN(Q10*Forutsetninger!$B$65+R10*Forutsetninger!$B$66,P10) -> 13709.52 | U10: =S10-T10 -> 18882.36 | V10: =MIN(U10,(P10-T10)/Forutsetninger!$B$54,Forutsetninger!$B$53*Forutsetninger!$B$55*B10) -> 12600 | W10: =V10*Forutsetninger!$B$54 -> 11340 | X10: =V10-W10 -> 1260 | Y10: =P10-T10-W10 -> 11877.98 | Z10: =U10-V10 -> 6282.36 | AA10: =(T10+W10)/P10 -> 0.67834324 | AB10: =Y10*(Forutsetninger!$B$58*H10+Forutsetninger!$B$59) -> 24943.758 | AC10: =Z10*Forutsetninger!$B$61*H10 -> 4711.77 | AD10: =AB10-AC10 -> 20231.988 | AE10: =(I10+J10+K10)*(Forutsetninger!$B$58*H10+Forutsetninger!$B$59) -> 133155.75 | AF10: =AE10-AD10 -> 112923.76 | AG10: =(I10+J10+K10-Y10)*Forutsetninger!$B$62 -> 10305.904
A11: Mai | B11: 31 | C11: 0.08 | D11: 0.05 | E11: 0.16 | F11: 0.06 | G11: 0.06 | H11: 0.85 | I11: =Forutsetninger!$B$12*C11 -> 16800 | J11: =Forutsetninger!$B$11*C11 -> 4760 | K11: =Forutsetninger!$B$13*D11 -> 22500 | L11: =MIN(K11,Forutsetninger!$B$48*G11) -> 22500 | M11: =L11/Forutsetninger!$B$47 -> 6250 | N11: =K11-L11 -> 0 | O11: =Forutsetninger!$B$39*E11 -> 3200 | P11: =I11+J11+M11+N11+O11 -> 31010 | Q11: =Forutsetninger!$B$26*E11 -> 38970.72 | R11: =Forutsetninger!$B$35*F11 -> 2522.88 | S11: =Q11+R11 -> 41493.6 | T11: =MIN(Q11*Forutsetninger!$B$65+R11*Forutsetninger!$B$66,P11) -> 17102.016 | U11: =S11-T11 -> 24391.584 | V11: =MIN(U11,(P11-T11)/Forutsetninger!$B$54,Forutsetninger!$B$53*Forutsetninger!$B$55*B11) -> 13020 | W11: =V11*Forutsetninger!$B$54 -> 11718 | X11: =V11-W11 -> 1302 | Y11: =P11-T11-W11 -> 2189.984 | Z11: =U11-V11 -> 11371.584 | AA11: =(T11+W11)/P11 -> 0.92937814 | AB11: =Y11*(Forutsetninger!$B$58*H11+Forutsetninger!$B$59) -> 3941.9712 | AC11: =Z11*Forutsetninger!$B$61*H11 -> 7249.3848 | AD11: =AB11-AC11 -> -3307.4136 | AE11: =(I11+J11+K11)*(Forutsetninger!$B$58*H11+Forutsetninger!$B$59) -> 79308 | AF11: =AE11-AD11 -> 82615.414 | AG11: =(I11+J11+K11-Y11)*Forutsetninger!$B$62 -> 8374.0032
A12: Juni | B12: 30 | C12: 0.075 | D12: 0.02 | E12: 0.16 | F12: 0.05 | G12: 0.04 | H12: 0.75 | I12: =Forutsetninger!$B$12*C12 -> 15750 | J12: =Forutsetninger!$B$11*C12 -> 4462.5 | K12: =Forutsetninger!$B$13*D12 -> 9000 | L12: =MIN(K12,Forutsetninger!$B$48*G12) -> 9000 | M12: =L12/Forutsetninger!$B$47 -> 2500 | N12: =K12-L12 -> 0 | O12: =Forutsetninger!$B$39*E12 -> 3200 | P12: =I12+J12+M12+N12+O12 -> 25912.5 | Q12: =Forutsetninger!$B$26*E12 -> 38970.72 | R12: =Forutsetninger!$B$35*F12 -> 2102.4 | S12: =Q12+R12 -> 41073.12 | T12: =MIN(Q12*Forutsetninger!$B$65+R12*Forutsetninger!$B$66,P12) -> 16849.728 | U12: =S12-T12 -> 24223.392 | V12: =MIN(U12,(P12-T12)/Forutsetninger!$B$54,Forutsetninger!$B$53*Forutsetninger!$B$55*B12) -> 10069.747 | W12: =V12*Forutsetninger!$B$54 -> 9062.772 | X12: =V12-W12 -> 1006.9747 | Y12: =P12-T12-W12 -> 0 | Z12: =U12-V12 -> 14153.645 | AA12: =(T12+W12)/P12 -> 1 | AB12: =Y12*(Forutsetninger!$B$58*H12+Forutsetninger!$B$59) -> 0 | AC12: =Z12*Forutsetninger!$B$61*H12 -> 7961.4255 | AD12: =AB12-AC12 -> -7961.4255 | AE12: =(I12+J12+K12)*(Forutsetninger!$B$58*H12+Forutsetninger!$B$59) -> 46740 | AF12: =AE12-AD12 -> 54701.425 | AG12: =(I12+J12+K12-Y12)*Forutsetninger!$B$62 -> 5842.5
A13: Juli | B13: 31 | C13: 0.07 | D13: 0.01 | E13: 0.15 | F13: 0.05 | G13: 0.03 | H13: 0.7 | I13: =Forutsetninger!$B$12*C13 -> 14700 | J13: =Forutsetninger!$B$11*C13 -> 4165 | K13: =Forutsetninger!$B$13*D13 -> 4500 | L13: =MIN(K13,Forutsetninger!$B$48*G13) -> 4500 | M13: =L13/Forutsetninger!$B$47 -> 1250 | N13: =K13-L13 -> 0 | O13: =Forutsetninger!$B$39*E13 -> 3000 | P13: =I13+J13+M13+N13+O13 -> 23115 | Q13: =Forutsetninger!$B$26*E13 -> 36535.05 | R13: =Forutsetninger!$B$35*F13 -> 2102.4 | S13: =Q13+R13 -> 38637.45 | T13: =MIN(Q13*Forutsetninger!$B$65+R13*Forutsetninger!$B$66,P13) -> 15875.46 | U13: =S13-T13 -> 22761.99 | V13: =MIN(U13,(P13-T13)/Forutsetninger!$B$54,Forutsetninger!$B$53*Forutsetninger!$B$55*B13) -> 8043.9333 | W13: =V13*Forutsetninger!$B$54 -> 7239.54 | X13: =V13-W13 -> 804.39333 | Y13: =P13-T13-W13 -> 0 | Z13: =U13-V13 -> 14718.057 | AA13: =(T13+W13)/P13 -> 1 | AB13: =Y13*(Forutsetninger!$B$58*H13+Forutsetninger!$B$59) -> 0 | AC13: =Z13*Forutsetninger!$B$61*H13 -> 7726.9797 | AD13: =AB13-AC13 -> -7726.9797 | AE13: =(I13+J13+K13)*(Forutsetninger!$B$58*H13+Forutsetninger!$B$59) -> 35047.5 | AF13: =AE13-AD13 -> 42774.48 | AG13: =(I13+J13+K13-Y13)*Forutsetninger!$B$62 -> 4673
A14: August | B14: 31 | C14: 0.07 | D14: 0.02 | E14: 0.12 | F14: 0.06 | G14: 0.04 | H14: 0.78 | I14: =Forutsetninger!$B$12*C14 -> 14700 | J14: =Forutsetninger!$B$11*C14 -> 4165 | K14: =Forutsetninger!$B$13*D14 -> 9000 | L14: =MIN(K14,Forutsetninger!$B$48*G14) -> 9000 | M14: =L14/Forutsetninger!$B$47 -> 2500 | N14: =K14-L14 -> 0 | O14: =Forutsetninger!$B$39*E14 -> 2400 | P14: =I14+J14+M14+N14+O14 -> 23765 | Q14: =Forutsetninger!$B$26*E14 -> 29228.04 | R14: =Forutsetninger!$B$35*F14 -> 2522.88 | S14: =Q14+R14 -> 31750.92 | T14: =MIN(Q14*Forutsetninger!$B$65+R14*Forutsetninger!$B$66,P14) -> 13204.944 | U14: =S14-T14 -> 18545.976 | V14: =MIN(U14,(P14-T14)/Forutsetninger!$B$54,Forutsetninger!$B$53*Forutsetninger!$B$55*B14) -> 11733.396 | W14: =V14*Forutsetninger!$B$54 -> 10560.056 | X14: =V14-W14 -> 1173.3396 | Y14: =P14-T14-W14 -> 0 | Z14: =U14-V14 -> 6812.5804 | AA14: =(T14+W14)/P14 -> 1 | AB14: =Y14*(Forutsetninger!$B$58*H14+Forutsetninger!$B$59) -> 0 | AC14: =Z14*Forutsetninger!$B$61*H14 -> 3985.3596 | AD14: =AB14-AC14 -> -3985.3596 | AE14: =(I14+J14+K14)*(Forutsetninger!$B$58*H14+Forutsetninger!$B$59) -> 46255.9 | AF14: =AE14-AD14 -> 50241.26 | AG14: =(I14+J14+K14-Y14)*Forutsetninger!$B$62 -> 5573
A15: September | B15: 30 | C15: 0.08 | D15: 0.05 | E15: 0.09 | F15: 0.07 | G15: 0.06 | H15: 0.88 | I15: =Forutsetninger!$B$12*C15 -> 16800 | J15: =Forutsetninger!$B$11*C15 -> 4760 | K15: =Forutsetninger!$B$13*D15 -> 22500 | L15: =MIN(K15,Forutsetninger!$B$48*G15) -> 22500 | M15: =L15/Forutsetninger!$B$47 -> 6250 | N15: =K15-L15 -> 0 | O15: =Forutsetninger!$B$39*E15 -> 1800 | P15: =I15+J15+M15+N15+O15 -> 29610 | Q15: =Forutsetninger!$B$26*E15 -> 21921.03 | R15: =Forutsetninger!$B$35*F15 -> 2943.36 | S15: =Q15+R15 -> 24864.39 | T15: =MIN(Q15*Forutsetninger!$B$65+R15*Forutsetninger!$B$66,P15) -> 10534.428 | U15: =S15-T15 -> 14329.962 | V15: =MIN(U15,(P15-T15)/Forutsetninger!$B$54,Forutsetninger!$B$53*Forutsetninger!$B$55*B15) -> 12600 | W15: =V15*Forutsetninger!$B$54 -> 11340 | X15: =V15-W15 -> 1260 | Y15: =P15-T15-W15 -> 7735.572 | Z15: =U15-V15 -> 1729.962 | AA15: =(T15+W15)/P15 -> 0.73875137 | AB15: =Y15*(Forutsetninger!$B$58*H15+Forutsetninger!$B$59) -> 14388.164 | AC15: =Z15*Forutsetninger!$B$61*H15 -> 1141.7749 | AD15: =AB15-AC15 -> 13246.389 | AE15: =(I15+J15+K15)*(Forutsetninger!$B$58*H15+Forutsetninger!$B$59) -> 81951.6 | AF15: =AE15-AD15 -> 68705.211 | AG15: =(I15+J15+K15-Y15)*Forutsetninger!$B$62 -> 7264.8856
A16: Oktober | B16: 31 | C16: 0.085 | D16: 0.09 | E16: 0.05 | F16: 0.09 | G16: 0.08 | H16: 1 | I16: =Forutsetninger!$B$12*C16 -> 17850 | J16: =Forutsetninger!$B$11*C16 -> 5057.5 | K16: =Forutsetninger!$B$13*D16 -> 40500 | L16: =MIN(K16,Forutsetninger!$B$48*G16) -> 39987.692 | M16: =L16/Forutsetninger!$B$47 -> 11107.692 | N16: =K16-L16 -> 512.30769 | O16: =Forutsetninger!$B$39*E16 -> 1000 | P16: =I16+J16+M16+N16+O16 -> 35527.5 | Q16: =Forutsetninger!$B$26*E16 -> 12178.35 | R16: =Forutsetninger!$B$35*F16 -> 3784.32 | S16: =Q16+R16 -> 15962.67 | T16: =MIN(Q16*Forutsetninger!$B$65+R16*Forutsetninger!$B$66,P16) -> 7141.932 | U16: =S16-T16 -> 8820.738 | V16: =MIN(U16,(P16-T16)/Forutsetninger!$B$54,Forutsetninger!$B$53*Forutsetninger!$B$55*B16) -> 8820.738 | W16: =V16*Forutsetninger!$B$54 -> 7938.6642 | X16: =V16-W16 -> 882.0738 | Y16: =P16-T16-W16 -> 20446.904 | Z16: =U16-V16 -> 0 | AA16: =(T16+W16)/P16 -> 0.42447671 | AB16: =Y16*(Forutsetninger!$B$58*H16+Forutsetninger!$B$59) -> 42938.498 | AC16: =Z16*Forutsetninger!$B$61*H16 -> 0 | AD16: =AB16-AC16 -> 42938.498 | AE16: =(I16+J16+K16)*(Forutsetninger!$B$58*H16+Forutsetninger!$B$59) -> 133155.75 | AF16: =AE16-AD16 -> 90217.252 | AG16: =(I16+J16+K16-Y16)*Forutsetninger!$B$62 -> 8592.1192
A17: November | B17: 30 | C17: 0.09 | D17: 0.12 | E17: 0.02 | F17: 0.11 | G17: 0.11 | H17: 1.14 | I17: =Forutsetninger!$B$12*C17 -> 18900 | J17: =Forutsetninger!$B$11*C17 -> 5355 | K17: =Forutsetninger!$B$13*D17 -> 54000 | L17: =MIN(K17,Forutsetninger!$B$48*G17) -> 54000 | M17: =L17/Forutsetninger!$B$47 -> 15000 | N17: =K17-L17 -> 0 | O17: =Forutsetninger!$B$39*E17 -> 400 | P17: =I17+J17+M17+N17+O17 -> 39655 | Q17: =Forutsetninger!$B$26*E17 -> 4871.34 | R17: =Forutsetninger!$B$35*F17 -> 4625.28 | S17: =Q17+R17 -> 9496.62 | T17: =MIN(Q17*Forutsetninger!$B$65+R17*Forutsetninger!$B$66,P17) -> 4723.704 | U17: =S17-T17 -> 4772.916 | V17: =MIN(U17,(P17-T17)/Forutsetninger!$B$54,Forutsetninger!$B$53*Forutsetninger!$B$55*B17) -> 4772.916 | W17: =V17*Forutsetninger!$B$54 -> 4295.6244 | X17: =V17-W17 -> 477.2916 | Y17: =P17-T17-W17 -> 30635.672 | Z17: =U17-V17 -> 0 | AA17: =(T17+W17)/P17 -> 0.22744492 | AB17: =Y17*(Forutsetninger!$B$58*H17+Forutsetninger!$B$59) -> 72912.898 | AC17: =Z17*Forutsetninger!$B$61*H17 -> 0 | AD17: =AB17-AC17 -> 72912.898 | AE17: =(I17+J17+K17)*(Forutsetninger!$B$58*H17+Forutsetninger!$B$59) -> 186246.9 | AF17: =AE17-AD17 -> 113334 | AG17: =(I17+J17+K17-Y17)*Forutsetninger!$B$62 -> 9523.8657
A18: Desember | B18: 31 | C18: 0.09 | D18: 0.15 | E18: 0.01 | F18: 0.13 | G18: 0.14 | H18: 1.2 | I18: =Forutsetninger!$B$12*C18 -> 18900 | J18: =Forutsetninger!$B$11*C18 -> 5355 | K18: =Forutsetninger!$B$13*D18 -> 67500 | L18: =MIN(K18,Forutsetninger!$B$48*G18) -> 67500 | M18: =L18/Forutsetninger!$B$47 -> 18750 | N18: =K18-L18 -> 0 | O18: =Forutsetninger!$B$39*E18 -> 200 | P18: =I18+J18+M18+N18+O18 -> 43205 | Q18: =Forutsetninger!$B$26*E18 -> 2435.67 | R18: =Forutsetninger!$B$35*F18 -> 5466.24 | S18: =Q18+R18 -> 7901.91 | T18: =MIN(Q18*Forutsetninger!$B$65+R18*Forutsetninger!$B$66,P18) -> 4254.012 | U18: =S18-T18 -> 3647.898 | V18: =MIN(U18,(P18-T18)/Forutsetninger!$B$54,Forutsetninger!$B$53*Forutsetninger!$B$55*B18) -> 3647.898 | W18: =V18*Forutsetninger!$B$54 -> 3283.1082 | X18: =V18-W18 -> 364.7898 | Y18: =P18-T18-W18 -> 35667.88 | Z18: =U18-V18 -> 0 | AA18: =(T18+W18)/P18 -> 0.17445018 | AB18: =Y18*(Forutsetninger!$B$58*H18+Forutsetninger!$B$59) -> 89169.699 | AC18: =Z18*Forutsetninger!$B$61*H18 -> 0 | AD18: =AB18-AC18 -> 89169.699 | AE18: =(I18+J18+K18)*(Forutsetninger!$B$58*H18+Forutsetninger!$B$59) -> 229387.5 | AF18: =AE18-AD18 -> 140217.8 | AG18: =(I18+J18+K18-Y18)*Forutsetninger!$B$62 -> 11217.424
A19: SUM ÅR | B19: =SUM(B7:B18) -> 365 | C19: =SUM(C7:C18) -> 1 | D19: =SUM(D7:D18) -> 1 | E19: =SUM(E7:E18) -> 1 | F19: =SUM(F7:F18) -> 1 | G19: =SUM(G7:G18) -> 1 | H19: =AVERAGE(H7:H18) -> 1 | I19: =SUM(I7:I18) -> 210000 | J19: =SUM(J7:J18) -> 59500 | K19: =SUM(K7:K18) -> 450000 | L19: =SUM(L7:L18) -> 444960 | M19: =SUM(M7:M18) -> 123600 | N19: =SUM(N7:N18) -> 5040 | O19: =SUM(O7:O18) -> 20000 | P19: =SUM(P7:P18) -> 418140 | ... Z19: =SUM(Z7:Z18) -> 55253.132 | AA19: =(T19+W19)/P19 -> 0.52516201 | AB19: =SUM(AB7:AB18) -> 481669.2 | AC19: =SUM(AC7:AC18) -> 32936.209 | AD19: =SUM(AD7:AD18) -> 448732.99 | AE19: =SUM(AE7:AE18) -> 1625600.6 | AF19: =SUM(AF7:AF18) -> 1176867.7 | AG19: =SUM(AG7:AG18) -> 104190.25
A21: NØKKELTALL FOR ÅRET
A22: Totalt el-behov (boliger, næringsbygg, bergvarme) | C22: =P19 -> 418140 | D22: kWh
A23: Egenprodusert energi (solstrøm + vindkraft) | C23: =S19 -> 285615 | D23: kWh
A24: Lagret og gjenbrukt via batteri | C24: =W19 -> 96935.641 | D24: kWh
A25: Strøm brukt til regenerering av berg | C25: =O19 -> 20000 | D25: kWh
A26: Overskudd solgt til nett | C26: =Z19 -> 55253.132 | D26: kWh
A27: Selvforsyningsgrad strøm | C27: =AA19 -> 0.52516201 | D27: %
A28: Netto energikostnad | C28: =AD19 -> 448732.99 | D28: kr/år
A29: Besparelse mot referanse | C29: =AF19 -> 1176867.7 | D29: kr/år
A30: Besparelse per bolig (forenklet fordeling) | C30: =AF19/Forutsetninger!$B$6 -> 39228.922 | D30: kr/år
A31: Spart CO₂ | C31: =AG19 -> 104190.25 | D31: kg/år
A33: DIAGRAMGRUNNLAG – ENERGIDEKNING PER MÅNED (kWh)
A34: Måned | B34: Miljøvarme fra brønner | C34: Egenprodusert brukt direkte | D34: Egenprodusert via batteri | E34: Kjøpt strøm fra nett | F34: Solgt til nett
A35: =A7 -> Januar | B35: =L7-M7 -> 48750 | C35: =T7 -> 3749.436 | D35: =W7 -> 2980.3626 | E35: =Y7 -> 37822.701 | F35: =Z7 -> 0
A36: =A8 -> Februar | B36: =L8-M8 -> 42250 | C36: =T8 -> 5445.684 | D36: =W8 -> 5459.5134 | E36: =Y8 -> 30199.803 | F36: =Z8 -> 0
A37: =A9 -> Mars | B37: =L9-M9 -> 36100 | C37: =T9 -> 10064.736 | D37: =W9 -> 11718 | E37: =Y9 -> 21972.264 | F37: =Z9 -> 184.944
A38: =A10 -> April | B38: =L10-M10 -> 28880 | C38: =T10 -> 13709.52 | D38: =W10 -> 11340 | E38: =Y10 -> 11877.98 | F38: =Z10 -> 6282.36
A39: =A11 -> Mai | B39: =L11-M11 -> 16250 | C39: =T11 -> 17102.016 | D39: =W11 -> 11718 | E39: =Y11 -> 2189.984 | F39: =Z11 -> 11371.584
A40: =A12 -> Juni | B40: =L12-M12 -> 6500 | C40: =T12 -> 16849.728 | D40: =W12 -> 9062.772 | E40: =Y12 -> 0 | F40: =Z12 -> 14153.645
A41: =A13 -> Juli | B41: =L13-M13 -> 3250 | C41: =T13 -> 15875.46 | D41: =W13 -> 7239.54 | E41: =Y13 -> 0 | F41: =Z13 -> 14718.057
A42: =A14 -> August | B42: =L14-M14 -> 6500 | C42: =T14 -> 13204.944 | D42: =W14 -> 10560.056 | E42: =Y14 -> 0 | F42: =Z14 -> 6812.5804
A43: =A15 -> September | B43: =L15-M15 -> 16250 | C43: =T15 -> 10534.428 | D43: =W15 -> 11340 | E43: =Y15 -> 7735.572 | F43: =Z15 -> 1729.962
...
